<?xml version="1.0" encoding="utf-8"?>
<!-- =================================================================================== -->
<!-- |    This document was autogenerated by xacro from car.xacro                      | -->
<!-- |    EDITING THIS FILE BY HAND IS NOT RECOMMENDED                                 | -->
<!-- =================================================================================== -->
<robot name="model_car" xmlns:xacro="http://www.ros.org/wiki/xacro">
  <material name="Black">
    <color rgba="0.0 0.0 0.0 1.0"/>
  </material>
  <material name="Blue">
    <color rgba="0.0 0.0 0.8 1.0"/>
  </material>
  <material name="Green">
    <color rgba="0.0 0.8 0.0 1.0"/>
  </material>
  <material name="Grey">
    <color rgba="0.7 0.7 0.7 1.0"/>
  </material>
  <material name="Grey2">
    <color rgba="0.9 0.9 0.9 1.0"/>
  </material>
  <material name="Red">
    <color rgba="0.8 0.0 0.0 1.0"/>
  </material>
  <material name="White">
    <color rgba="1.0 1.0 1.0 1.0"/>
  </material>
  <link name="base_link">
    </link>
  <link name="body">
    <inertial>
      <mass value="6"/>
      <origin xyz="0.15971917 0.00000000 0.00197764"/>
      <inertia ixx="0.0067970" ixy="0.0" ixz="-0.0008808" iyy="0.0784672" iyz="0.0" izz="0.0838770"/>
    </inertial>
    <visual>
      <origin rpy="0 0 0" xyz="0 0 0"/>
      <geometry>
        <mesh filename="package://car_robot_model/meshes/chassis.stl"/>
      </geometry>
      <material name="Black"/>
    </visual>
    <collision>
      <origin rpy="0 0 0" xyz="0 0 0"/>
      <geometry>
        <mesh filename="package://car_robot_model/meshes/chassis.stl"/>
      </geometry>
    </collision>
  </link>
  <joint name="base_link_to_body" type="fixed">
    <origin rpy="0 0 0" xyz="0.0 0 0.005"/>
    <parent link="base_link"/>
    <child link="body"/>
  </joint>
  <joint name="base_link_rear_left_wheel_joint" type="revolute">
    <origin rpy="1.57079632679 0 0" xyz="0.0 -0.0825 0.03"/>
    <axis xyz="0 0 1"/>
    <anchor xyz="0 0 0"/>
    <parent link="base_link"/>
    <child link="rear_left_wheel_link"/>
    <limit effort="3.0" lower="-1000000000000.0" upper="1000000000000.0" velocity="124"/>
  </joint>
  <transmission name="tran_rear_left">
    <type>transmission_interface/SimpleTransmission</type>
    <joint name="base_link_rear_left_wheel_joint">
      <hardwareInterface>hardware_interface/EffortJointInterface</hardwareInterface>
    </joint>
    <actuator name="rear_left_motor">
      <hardwareInterface>hardware_interface/EffortJointInterface</hardwareInterface>
      <mechanicalReduction>1</mechanicalReduction>
    </actuator>
  </transmission>
  <link name="rear_left_wheel_link">
    <inertial>
      <mass value="1"/>
      <origin rpy="0 0 0" xyz="0 0 0"/>
      <inertia ixx="0.0002946" ixy="0.0" ixz="0.0" iyy="0.0002946" iyz="0.0" izz="0.000494"/>
    </inertial>
    <visual>
      <origin rpy="0 0 0" xyz="0 0 0"/>
      <geometry>
        <mesh filename="package://car_robot_model/meshes/wheel.stl"/>
      </geometry>
      <material name="Black"/>
    </visual>
    <collision>
      <origin rpy="0 0 0" xyz="0 0 0"/>
      <geometry>
        <cylinder length="0.001" radius="0.0315"/>
      </geometry>
    </collision>
  </link>
  <joint name="base_link_rear_right_wheel_joint" type="revolute">
    <origin rpy="-1.57079632679 0 0" xyz="0.0 0.0825 0.03"/>
    <axis xyz="0 0 1"/>
    <anchor xyz="0 0 0"/>
    <parent link="base_link"/>
    <child link="rear_right_wheel_link"/>
    <limit effort="3.0" lower="-1000000000000.0" upper="1000000000000.0" velocity="124"/>
  </joint>
  <transmission name="tran_rear_right">
    <type>transmission_interface/SimpleTransmission</type>
    <joint name="base_link_rear_right_wheel_joint">
      <hardwareInterface>hardware_interface/EffortJointInterface</hardwareInterface>
    </joint>
    <actuator name="rear_right_motor">
      <hardwareInterface>hardware_interface/EffortJointInterface</hardwareInterface>
      <mechanicalReduction>1</mechanicalReduction>
    </actuator>
  </transmission>
  <link name="rear_right_wheel_link">
    <inertial>
      <mass value="1"/>
      <origin rpy="0 0 0" xyz="0 0 0"/>
      <inertia ixx="0.0002946" ixy="0.0" ixz="0.0" iyy="0.0002946" iyz="0.0" izz="0.0004940"/>
    </inertial>
    <visual>
      <origin rpy="0 0 0" xyz="0 0 0"/>
      <geometry>
        <mesh filename="package://car_robot_model/meshes/wheel.stl"/>
      </geometry>
      <material name="Black"/>
    </visual>
    <collision>
      <origin rpy="0 0 0" xyz="0 0 0"/>
      <geometry>
        <cylinder length="0.001" radius="0.0315"/>
      </geometry>
    </collision>
  </link>
  <joint name="base_link_front_left_axel_joint" type="revolute">
    <origin rpy="1.57079632679 0 0" xyz="0.260 -0.0825 0.03"/>
    <axis xyz="0 1 0"/>
    <anchor xyz="0 0 0"/>
    <parent link="base_link"/>
    <child link="front_left_axel_link"/>
    <limit effort="9.6" lower="-1.0471975512" upper="1.0471975512" velocity="5.3"/>
    <dynamics damping="0.2"/>
  </joint>
  <transmission name="tran_front_left_axel">
    <type>transmission_interface/SimpleTransmission</type>
    <joint name="base_link_front_left_axel_joint">
      <hardwareInterface>hardware_interface/EffortJointInterface</hardwareInterface>
    </joint>
    <actuator name="front_left_axel_motor">
      <hardwareInterface>hardware_interface/EffortJointInterface</hardwareInterface>
      <mechanicalReduction>1</mechanicalReduction>
    </actuator>
  </transmission>
  <link name="front_left_axel_link">
    <inertial>
      <mass value="0.001"/>
      <origin rpy="0 0 0" xyz="0 0 0"/>
      <inertia ixx="0.00001" ixy="0.0" ixz="0.0" iyy="0.00001" iyz="0.0" izz="0.00001"/>
    </inertial>
  </link>
  <joint name="front_left_axel_front_left_wheel_joint" type="revolute">
    <origin rpy="0 0 0" xyz="0.0 0.0 0"/>
    <axis xyz="0 0 1"/>
    <anchor xyz="0 0 0"/>
    <parent link="front_left_axel_link"/>
    <child link="front_left_wheel_link"/>
    <limit effort="3.0" lower="-1000000000000.0" upper="1000000000000.0" velocity="124"/>
  </joint>
  <transmission name="tran_front_left_wheel">
    <type>transmission_interface/SimpleTransmission</type>
    <joint name="front_left_axel_front_left_wheel_joint">
      <hardwareInterface>hardware_interface/EffortJointInterface</hardwareInterface>
    </joint>
    <actuator name="front_left_wheel_motor">
      <hardwareInterface>hardware_interface/EffortJointInterface</hardwareInterface>
      <mechanicalReduction>1</mechanicalReduction>
    </actuator>
  </transmission>
  <link name="front_left_wheel_link">
    <inertial>
      <mass value="1"/>
      <origin rpy="0 0 0" xyz="0 0 0"/>
      <inertia ixx="0.0002946" ixy="0.0" ixz="0.0" iyy="0.0002946" iyz="0.0" izz="0.0004940"/>
    </inertial>
    <visual>
      <origin rpy="0 0 0" xyz="0 0 0"/>
      <geometry>
        <mesh filename="package://car_robot_model/meshes/wheel.stl"/>
      </geometry>
      <material name="Black"/>
    </visual>
    <collision>
      <origin rpy="0 0 0" xyz="0 0 0"/>
      <geometry>
        <cylinder length="0.001" radius="0.0315"/>
      </geometry>
    </collision>
  </link>
  <joint name="base_link_front_right_axel_joint" type="revolute">
    <origin rpy="-1.57079632679 0 0" xyz="0.260 0.0825 0.03"/>
    <axis xyz="0 1 0"/>
    <anchor xyz="0 0 0"/>
    <parent link="base_link"/>
    <child link="front_right_axel_link"/>
    <limit effort="9.6" lower="-1.0471975512" upper="1.0471975512" velocity="5.3"/>
    <dynamics damping="0.2"/>
  </joint>
  <transmission name="tran_front_right_axel">
    <type>transmission_interface/SimpleTransmission</type>
    <joint name="base_link_front_right_axel_joint">
      <hardwareInterface>hardware_interface/EffortJointInterface</hardwareInterface>
    </joint>
    <actuator name="front_right_axel_motor">
      <hardwareInterface>hardware_interface/EffortJointInterface</hardwareInterface>
      <mechanicalReduction>1</mechanicalReduction>
    </actuator>
  </transmission>
  <link name="front_right_axel_link">
    <inertial>
      <mass value="0.001"/>
      <origin rpy="0 0 0" xyz="0 0 0"/>
      <inertia ixx="0.00001" ixy="0.0" ixz="0.0" iyy="0.00001" iyz="0.0" izz="0.00001"/>
    </inertial>
  </link>
  <joint name="front_right_axel_front_right_wheel_joint" type="continuous">
    <origin rpy="0 0 0" xyz="0.0 0.0 0"/>
    <axis xyz="0 0 1"/>
    <anchor xyz="0 0 0"/>
    <parent link="front_right_axel_link"/>
    <child link="front_right_wheel_link"/>
    <limit effort="3.0" lower="-1000000000000.0" upper="1000000000000.0" velocity="124"/>
  </joint>
  <transmission name="tran_front_right_wheel">
    <type>transmission_interface/SimpleTransmission</type>
    <joint name="front_right_axel_front_right_wheel_joint">
      <hardwareInterface>hardware_interface/EffortJointInterface</hardwareInterface>
    </joint>
    <actuator name="front_right_wheel_motor">
      <hardwareInterface>hardware_interface/EffortJointInterface</hardwareInterface>
      <mechanicalReduction>1</mechanicalReduction>
    </actuator>
  </transmission>
  <link name="front_right_wheel_link">
    <inertial>
      <mass value="1"/>
      <origin rpy="0 0 0" xyz="0 0 0"/>
      <inertia ixx="0.0002946" ixy="0.0" ixz="0.0" iyy="0.0002946" iyz="0.0" izz="0.0004940"/>
    </inertial>
    <visual>
      <origin rpy="0 0 0" xyz="0 0 0"/>
      <geometry>
        <mesh filename="package://car_robot_model/meshes/wheel.stl"/>
      </geometry>
      <material name="Black"/>
    </visual>
    <collision>
      <origin rpy="0 0 0" xyz="0 0 0"/>
      <geometry>
        <cylinder length="0.001" radius="0.0315"/>
      </geometry>
    </collision>
  </link>
  <link name="sensor_board">
    <inertial>
      <mass value="6"/>
      <origin rpy="0 0 0" xyz="0.12043628 0.00000000 0.00171950"/>
      <inertia ixx="0.0123739" ixy="0.0" ixz="0.0003463" iyy="0.0711051" iyz="0.0" izz="0.0820107"/>
    </inertial>
    <visual>
      <origin rpy="0 0 0" xyz="0.0 0.0 0.0"/>
      <geometry>
        <mesh filename="package://car_robot_model/meshes/sensor_board.stl"/>
      </geometry>
      <material name="Grey"/>
    </visual>
    <collision>
      <origin rpy="0 0 0" xyz="0.0 0.0 0.0"/>
      <geometry>
        <mesh filename="package://car_robot_model/meshes/sensor_board.stl"/>
      </geometry>
    </collision>
  </link>
  <joint name="joint_base_link_to_sensor_board" type="fixed">
    <parent link="base_link"/>
    <child link="sensor_board"/>
    <origin rpy="0 0 0" xyz="0 0 0.07"/>
  </joint>
  <link name="camera_board">
    <inertial>
      <mass value="0.6000000"/>
      <origin rpy="0 0 0" xyz="0.04901990 0.00000000 0.00000000"/>
      <inertia ixx="0.0003816" ixy="0.0" ixz="0.0" iyy="0.0003420" iyz="0.0" izz="0.0007211"/>
    </inertial>
    <visual>
      <origin rpy="0 0 0" xyz="0.0 0.0 0.0"/>
      <geometry>
        <mesh filename="package://car_robot_model/meshes/camera_board.stl"/>
      </geometry>
      <material name="Grey"/>
    </visual>
    <collision>
      <origin rpy="0 0 0" xyz="0.0 0.0 0.0"/>
      <geometry>
        <mesh filename="package://car_robot_model/meshes/camera_board.stl"/>
      </geometry>
    </collision>
  </link>
  <joint name="joint_sensor_board_to_camera_board" type="fixed">
    <parent link="sensor_board"/>
    <child link="camera_board"/>
    <origin rpy="0 0 0" xyz="-0.07 0 0.15"/>
  </joint>
  <!--*************************************************-->
  <!--*               Sensors                         *-->
  <!--*************************************************-->
  <!-- IMU -->
  <link name="imu">
    <inertial>
      <mass value="0.0200000"/>
      <origin rpy="0 0 0" xyz="0.00000000 0.00000000 0.00150000"/>
      <inertia ixx="0.0000007" ixy="0.0" ixz="0.0" iyy="0.0000004" iyz="0.0" izz="0.0000011"/>
    </inertial>
    <visual>
      <origin rpy="0 0 0" xyz="0 0 0"/>
      <geometry>
        <mesh filename="package://car_robot_model/meshes/IMU.stl"/>
      </geometry>
      <material name="Black"/>
    </visual>
    <collision>
      <origin rpy="0 0 0" xyz="0 0 0"/>
      <geometry>
        <mesh filename="package://car_robot_model/meshes/IMU.stl"/>
      </geometry>
    </collision>
  </link>
  <joint name="joint_sensor_board_to_imu" type="fixed">
    <parent link="sensor_board"/>
    <child link="imu"/>
    <origin rpy="0 0 0" xyz="0.035 -0.035 0.0025"/>
  </joint>
  <!-- BNO055 -->
  <link name="bno055">
    </link>
  <joint name="joint_sensor_board_to_bno055" type="fixed">
    <parent link="sensor_board"/>
    <child link="bno055"/>
    <origin rpy="0 0 0" xyz="0.235 0.0 0.023"/>
  </joint>
  <!-- Odroid -->
  <link name="odroid">
    <inertial>
      <mass value="0.2000000"/>
      <origin rpy="0 0 0" xyz="0.00000000 0.00000000 0.00000000"/>
      <inertia ixx="0.00000000" ixy="0.0" ixz="0.0" iyy="0.00000000" iyz="0.0" izz="0.00000000"/>
    </inertial>
    <visual>
      <origin rpy="0 0 0" xyz="0 0 0.01"/>
      <geometry>
        <box size="0.06 0.08 0.015"/>
      </geometry>
      <material name="Black"/>
    </visual>
  </link>
  <joint name="joint_sensor_board_to_odroid" type="fixed">
    <parent link="sensor_board"/>
    <child link="odroid"/>
    <origin rpy="0 0 0" xyz="-0.04 0 0"/>
  </joint>
  <!-- Aruco Marker -->
  <link name="marker">
    </link>
  <joint name="joint_sensor_board_to_marker" type="fixed">
    <parent link="sensor_board"/>
    <child link="marker"/>
    <origin rpy="0 0 0" xyz="0.30 0 0"/>
  </joint>
  <joint name="lidar_base_joint" type="fixed">
    <origin rpy="0 0 0" xyz="0.21 0 0"/>
    <parent link="sensor_board"/>
    <child link="lidar_base_link"/>
  </joint>
  <link name="lidar_base_link">
    <collision>
      <origin rpy="0 0 0" xyz="0 0 0"/>
      <geometry>
        <mesh filename="package://car_robot_model/meshes/rplidar_a2.dae"/>
      </geometry>
    </collision>
    <visual>
      <origin rpy="0 0 0" xyz="0 0 0"/>
      <geometry>
        <mesh filename="package://car_robot_model/meshes/rplidar_a2.dae"/>
      </geometry>
      <material name="Black"/>
    </visual>
    <inertial>
      <mass value="1e-5"/>
      <origin rpy="0 0 0" xyz="0 0 0"/>
      <inertia ixx="1e-6" ixy="0" ixz="0" iyy="1e-6" iyz="0" izz="1e-6"/>
    </inertial>
  </link>
  <joint name="lidar_laser_joint" type="fixed">
    <origin rpy="0 0 3.1415" xyz="0 0 0.03086"/>
    <parent link="lidar_base_link"/>
    <child link="laser"/>
  </joint>
  <link name="laser">
        </link>
  <material name="aluminum">
    <color rgba="0.5 0.5 0.5 1"/>
  </material>
  <!-- camera body, with origin at bottom screw mount -->
  <joint name="camera_joint" type="fixed">
    <origin rpy="0 0.15 0" xyz="0.087 0 0.04"/>
    <parent link="camera_board"/>
    <child link="camera_bottom_screw_frame"/>
  </joint>
  <link name="camera_bottom_screw_frame"/>
  <joint name="camera_link_joint" type="fixed">
    <origin rpy="0 0 0" xyz="0 0.0175 0.0125"/>
    <parent link="camera_bottom_screw_frame"/>
    <child link="camera_link"/>
  </joint>
  <link name="camera_link">
    <visual>
      <origin rpy="1.57079632679 0 1.57079632679" xyz="0.0149 -0.0175 0"/>
      <geometry>
        <!-- <box size="${d435_cam_width} ${d435_cam_height} ${d435_cam_depth}"/> -->
        <mesh filename="package://car_robot_model/meshes/d435.dae"/>
        <!--<mesh filename="package://realsense2_camera/meshes/d435/d435.dae" />-->
      </geometry>
      <material name="aluminum"/>
    </visual>
    <collision>
      <origin rpy="0 0 0" xyz="0 -0.0175 0"/>
      <geometry>
        <box size="0.02505 0.09 0.025"/>
      </geometry>
    </collision>
    <inertial>
      <!-- The following are not reliable values, and should not be used for modeling -->
      <mass value="0.564"/>
      <origin xyz="0 0 0"/>
      <inertia ixx="0.003881243" ixy="0.0" ixz="0.0" iyy="0.000498940" iyz="0.0" izz="0.003879257"/>
    </inertial>
  </link>
  <!-- camera depth joints and links -->
  <joint name="camera_depth_joint" type="fixed">
    <origin rpy="0 0 0" xyz="0 0 0"/>
    <parent link="camera_link"/>
    <child link="camera_depth_frame"/>
  </joint>
  <link name="camera_depth_frame"/>
  <joint name="camera_depth_optical_joint" type="fixed">
    <origin rpy="-1.57079632679 0 -1.57079632679" xyz="0 0 0"/>
    <parent link="camera_depth_frame"/>
    <child link="camera_depth_optical_frame"/>
  </joint>
  <link name="camera_depth_optical_frame"/>
  <!-- camera left IR joints and links -->
  <joint name="camera_left_ir_joint" type="fixed">
    <origin rpy="0 0 0" xyz="0 0.0 0"/>
    <parent link="camera_depth_frame"/>
    <child link="camera_left_ir_frame"/>
  </joint>
  <link name="camera_left_ir_frame"/>
  <joint name="camera_left_ir_optical_joint" type="fixed">
    <origin rpy="-1.57079632679 0 -1.57079632679" xyz="0 0 0"/>
    <parent link="camera_left_ir_frame"/>
    <child link="camera_left_ir_optical_frame"/>
  </joint>
  <link name="camera_left_ir_optical_frame"/>
  <!-- camera right IR joints and links -->
  <joint name="camera_right_ir_joint" type="fixed">
    <origin rpy="0 0 0" xyz="0 -0.05 0"/>
    <parent link="camera_depth_frame"/>
    <child link="camera_right_ir_frame"/>
  </joint>
  <link name="camera_right_ir_frame"/>
  <joint name="camera_right_ir_optical_joint" type="fixed">
    <origin rpy="-1.57079632679 0 -1.57079632679" xyz="0 0 0"/>
    <parent link="camera_right_ir_frame"/>
    <child link="camera_right_ir_optical_frame"/>
  </joint>
  <link name="camera_right_ir_optical_frame"/>
  <!-- camera color joints and links -->
  <joint name="camera_color_joint" type="fixed">
    <origin rpy="0 0 0" xyz="0 0.015 0"/>
    <parent link="camera_depth_frame"/>
    <child link="camera_color_frame"/>
  </joint>
  <link name="camera_color_frame"/>
  <joint name="camera_color_optical_joint" type="fixed">
    <origin rpy="-1.57079632679 0 -1.57079632679" xyz="0 0 0"/>
    <parent link="camera_color_frame"/>
    <child link="camera_color_optical_frame"/>
  </joint>
  <link name="camera_color_optical_frame"/>
</robot>

